2025-08-14 17:54:48 - FundAnalysis - INFO - logger.py:91 - 基金数据爬取与分析系统启动
2025-08-14 17:54:48 - FundAnalysis - INFO - logger.py:91 - 系统时间: 2025-08-14 17:54:48
2025-08-14 17:54:48 - FundAnalysis - INFO - logger.py:91 - [基金分析系统] 开始执行 - 开始执行完整分析流程
2025-08-14 17:54:48 - FundAnalysis - INFO - logger.py:91 - ============================================================
2025-08-14 17:54:48 - FundAnalysis - INFO - logger.py:91 - 第一阶段：数据获取与爬取
2025-08-14 17:54:48 - FundAnalysis - INFO - logger.py:91 - ============================================================
2025-08-14 17:54:48 - FundAnalysis - INFO - logger.py:91 - [代理管理器初始化] 开始执行
2025-08-14 17:54:48 - FundAnalysis - INFO - logger.py:91 - 开始更新代理列表...
2025-08-14 17:54:48 - FundAnalysis - DEBUG - logger.py:87 - 从 https://raw.githubusercontent.com/clarketm/proxy-list/master/proxy-list-raw.txt 获取到 400 个代理
2025-08-14 17:54:48 - FundAnalysis - DEBUG - logger.py:87 - 从 https://raw.githubusercontent.com/sunny9577/proxy-scraper/master/proxies.txt 获取到 2254 个代理
2025-08-14 17:54:48 - FundAnalysis - DEBUG - logger.py:87 - 从 https://raw.githubusercontent.com/TheSpeedX/PROXY-List/master/http.txt 获取到 37950 个代理
2025-08-14 17:54:48 - FundAnalysis - DEBUG - logger.py:87 - 从 https://free-proxy-list.net/ 爬取到 300 个代理
2025-08-14 17:54:48 - FundAnalysis - DEBUG - logger.py:87 - 从 https://www.proxy-list.download/api/v1/get?type=http 获取到 90 个代理
2025-08-14 17:54:48 - FundAnalysis - DEBUG - logger.py:87 - 从 https://api.proxyscrape.com/v2/?request=get&protocol=http&timeout=10000&country=all 获取到 0 个代理
2025-08-14 17:54:49 - FundAnalysis - DEBUG - logger.py:87 - 从 https://www.proxynova.com/proxy-server-list/ 爬取到 0 个代理
2025-08-14 17:54:49 - FundAnalysis - INFO - logger.py:91 - 获取到 440 个唯一代理，开始检测...
2025-08-14 17:54:49 - FundAnalysis - DEBUG - logger.py:87 - 代理可用: 185.146.173.176:80 (成功率: 100.00%)
2025-08-14 17:54:49 - FundAnalysis - DEBUG - logger.py:87 - 代理检测失败 46.101.102.134:3128: HTTPConnectionPool(host='46.101.102.134', port=3128): Max retries exceeded with url: http://ident.me/ (Caused by ProxyError('Unable to connect to proxy', NewConnectionError('<urllib3.connection.HTTPConnection object at 0x7f7d3c845310>: Failed to establish a new connection: [Errno 111] Connection refused')))
2025-08-14 17:54:49 - FundAnalysis - DEBUG - logger.py:87 - 代理检测失败 85.214.94.28:3128: HTTPConnectionPool(host='85.214.94.28', port=3128): Max retries exceeded with url: http://icanhazip.com/ (Caused by ProxyError('Unable to connect to proxy', NewConnectionError('<urllib3.connection.HTTPConnection object at 0x7f7d3c8652d0>: Failed to establish a new connection: [Errno 111] Connection refused')))
2025-08-14 17:54:49 - FundAnalysis - DEBUG - logger.py:87 - 代理可用: 104.21.30.41:80 (成功率: 100.00%)
2025-08-14 17:54:49 - FundAnalysis - DEBUG - logger.py:87 - 代理检测失败 144.91.118.176:3128: HTTPConnectionPool(host='144.91.118.176', port=3128): Max retries exceeded with url: http://ident.me/ (Caused by ProxyError('Unable to connect to proxy', NewConnectionError('<urllib3.connection.HTTPConnection object at 0x7f7d3c834f10>: Failed to establish a new connection: [Errno 111] Connection refused')))
2025-08-14 17:54:49 - FundAnalysis - DEBUG - logger.py:87 - 代理检测失败 103.49.114.195:8080: HTTPConnectionPool(host='103.49.114.195', port=8080): Max retries exceeded with url: http://ident.me/ (Caused by ProxyError('Unable to connect to proxy', ConnectionResetError(104, 'Connection reset by peer')))
2025-08-14 17:54:49 - FundAnalysis - DEBUG - logger.py:87 - 代理可用: 181.174.164.221:80 (成功率: 100.00%)
2025-08-14 17:54:49 - FundAnalysis - DEBUG - logger.py:87 - 代理可用: 172.67.177.243:80 (成功率: 100.00%)
2025-08-14 17:54:50 - FundAnalysis - DEBUG - logger.py:87 - 代理可用: 203.19.38.114:1080 (成功率: 100.00%)
2025-08-14 17:54:50 - FundAnalysis - DEBUG - logger.py:87 - 代理检测失败 94.231.192.97:8080: HTTPConnectionPool(host='94.231.192.97', port=8080): Max retries exceeded with url: http://ident.me/ (Caused by ProxyError('Unable to connect to proxy', NewConnectionError('<urllib3.connection.HTTPConnection object at 0x7f7d3c842dd0>: Failed to establish a new connection: [Errno 111] Connection refused')))
2025-08-14 17:54:51 - FundAnalysis - DEBUG - logger.py:87 - 代理可用: 120.26.104.146:1111 (成功率: 100.00%)
2025-08-14 17:54:52 - FundAnalysis - DEBUG - logger.py:87 - 代理可用: 45.131.6.243:80 (成功率: 100.00%)
2025-08-14 17:54:54 - FundAnalysis - DEBUG - logger.py:87 - 代理可用: 47.122.57.58:8443 (成功率: 100.00%)
2025-08-14 17:54:54 - FundAnalysis - DEBUG - logger.py:87 - 代理可用: 190.103.177.131:80 (成功率: 100.00%)
2025-08-14 17:54:54 - FundAnalysis - DEBUG - logger.py:87 - 代理检测失败 181.65.169.35:999: HTTPConnectionPool(host='181.65.169.35', port=999): Max retries exceeded with url: http://ident.me/ (Caused by ProxyError('Unable to connect to proxy', NewConnectionError('<urllib3.connection.HTTPConnection object at 0x7f7d3c851fd0>: Failed to establish a new connection: [Errno 111] Connection refused')))
2025-08-14 17:54:56 - FundAnalysis - DEBUG - logger.py:87 - 代理可用: 200.201.134.184:8787 (成功率: 100.00%)
2025-08-14 17:54:56 - FundAnalysis - INFO - logger.py:91 - 已检测 20 个代理，发现 10 个可用
2025-08-14 17:54:59 - FundAnalysis - DEBUG - logger.py:87 - 代理检测失败 109.111.212.78:8080: HTTPConnectionPool(host='109.111.212.78', port=8080): Max retries exceeded with url: http://ipinfo.io/ip (Caused by ProxyError('Unable to connect to proxy', ConnectTimeoutError(<urllib3.connection.HTTPConnection object at 0x7f7d425a2c10>, 'Connection to 109.111.212.78 timed out. (connect timeout=10)')))
2025-08-14 17:54:59 - FundAnalysis - DEBUG - logger.py:87 - 代理检测失败 193.239.86.247:3128: HTTPConnectionPool(host='193.239.86.247', port=3128): Max retries exceeded with url: http://httpbin.org/ip (Caused by ProxyError('Unable to connect to proxy', ConnectTimeoutError(<urllib3.connection.HTTPConnection object at 0x7f7d3c824550>, 'Connection to 193.239.86.247 timed out. (connect timeout=10)')))
2025-08-14 17:54:59 - FundAnalysis - DEBUG - logger.py:87 - 代理检测失败 193.239.86.248:3128: HTTPConnectionPool(host='193.239.86.248', port=3128): Max retries exceeded with url: http://ipinfo.io/ip (Caused by ProxyError('Unable to connect to proxy', ConnectTimeoutError(<urllib3.connection.HTTPConnection object at 0x7f7d3c829290>, 'Connection to 193.239.86.248 timed out. (connect timeout=10)')))
2025-08-14 17:54:59 - FundAnalysis - DEBUG - logger.py:87 - 代理检测失败 131.72.69.209:8080: HTTPConnectionPool(host='131.72.69.209', port=8080): Max retries exceeded with url: http://icanhazip.com/ (Caused by ProxyError('Unable to connect to proxy', ConnectTimeoutError(<urllib3.connection.HTTPConnection object at 0x7f7d3c840850>, 'Connection to 131.72.69.209 timed out. (connect timeout=10)')))
2025-08-14 17:54:59 - FundAnalysis - DEBUG - logger.py:87 - 代理检测失败 183.164.254.8:4216: HTTPConnectionPool(host='183.164.254.8', port=4216): Max retries exceeded with url: http://ident.me/ (Caused by ProxyError('Unable to connect to proxy', ConnectTimeoutError(<urllib3.connection.HTTPConnection object at 0x7f7d3c847890>, 'Connection to 183.164.254.8 timed out. (connect timeout=10)')))
2025-08-14 17:54:59 - FundAnalysis - DEBUG - logger.py:87 - 代理检测失败 38.51.49.84:999: HTTPConnectionPool(host='38.51.49.84', port=999): Max retries exceeded with url: http://ident.me/ (Caused by ProxyError('Unable to connect to proxy', ConnectTimeoutError(<urllib3.connection.HTTPConnection object at 0x7f7d3c8746d0>, 'Connection to 38.51.49.84 timed out. (connect timeout=10)')))
2025-08-14 17:54:59 - FundAnalysis - DEBUG - logger.py:87 - 代理检测失败 181.74.81.195:999: HTTPConnectionPool(host='181.74.81.195', port=999): Max retries exceeded with url: http://httpbin.org/ip (Caused by ProxyError('Unable to connect to proxy', ConnectTimeoutError(<urllib3.connection.HTTPConnection object at 0x7f7d3c8849d0>, 'Connection to 181.74.81.195 timed out. (connect timeout=10)')))
2025-08-14 17:54:59 - FundAnalysis - DEBUG - logger.py:87 - 代理检测失败 82.165.105.48:80: HTTPConnectionPool(host='82.165.105.48', port=80): Max retries exceeded with url: http://icanhazip.com/ (Caused by ProxyError('Unable to connect to proxy', ConnectTimeoutError(<urllib3.connection.HTTPConnection object at 0x7f7d3c825cd0>, 'Connection to 82.165.105.48 timed out. (connect timeout=10)')))
2025-08-14 17:54:59 - FundAnalysis - DEBUG - logger.py:87 - 代理检测失败 190.113.40.202:999: HTTPConnectionPool(host='190.113.40.202', port=999): Max retries exceeded with url: http://icanhazip.com/ (Caused by ProxyError('Unable to connect to proxy', ConnectTimeoutError(<urllib3.connection.HTTPConnection object at 0x7f7d3c6d4f50>, 'Connection to 190.113.40.202 timed out. (connect timeout=10)')))
2025-08-14 17:54:59 - FundAnalysis - DEBUG - logger.py:87 - 代理检测失败 206.42.19.65:8080: HTTPConnectionPool(host='206.42.19.65', port=8080): Max retries exceeded with url: http://icanhazip.com/ (Caused by ProxyError('Unable to connect to proxy', ConnectTimeoutError(<urllib3.connection.HTTPConnection object at 0x7f7d3c887010>, 'Connection to 206.42.19.65 timed out. (connect timeout=10)')))
2025-08-14 17:54:59 - FundAnalysis - DEBUG - logger.py:87 - 代理检测失败 79.122.230.20:8080: HTTPConnectionPool(host='79.122.230.20', port=8080): Max retries exceeded with url: http://ident.me/ (Caused by ProxyError('Unable to connect to proxy', ConnectTimeoutError(<urllib3.connection.HTTPConnection object at 0x7f7d3c692310>, 'Connection to 79.122.230.20 timed out. (connect timeout=10)')))
2025-08-14 17:54:59 - FundAnalysis - DEBUG - logger.py:87 - 代理检测失败 200.115.100.33:8080: HTTPConnectionPool(host='200.115.100.33', port=8080): Max retries exceeded with url: http://httpbin.org/ip (Caused by ProxyError('Unable to connect to proxy', ConnectTimeoutError(<urllib3.connection.HTTPConnection object at 0x7f7d3c6d54d0>, 'Connection to 200.115.100.33 timed out. (connect timeout=10)')))
2025-08-14 17:54:59 - FundAnalysis - DEBUG - logger.py:87 - 代理可用: 5.182.34.226:80 (成功率: 100.00%)
2025-08-14 17:54:59 - FundAnalysis - DEBUG - logger.py:87 - 代理检测失败 207.180.250.238:80: HTTPConnectionPool(host='207.180.250.238', port=80): Max retries exceeded with url: http://icanhazip.com/ (Caused by ProxyError('Unable to connect to proxy', NewConnectionError('<urllib3.connection.HTTPConnection object at 0x7f7d3c828f50>: Failed to establish a new connection: [Errno 111] Connection refused')))
2025-08-14 17:54:59 - FundAnalysis - DEBUG - logger.py:87 - 代理检测失败 200.52.148.10:999: HTTPConnectionPool(host='200.52.148.10', port=999): Max retries exceeded with url: http://ipinfo.io/ip (Caused by ProxyError('Unable to connect to proxy', ConnectTimeoutError(<urllib3.connection.HTTPConnection object at 0x7f7d3c6dde90>, 'Connection to 200.52.148.10 timed out. (connect timeout=10)')))
2025-08-14 17:54:59 - FundAnalysis - DEBUG - logger.py:87 - 代理可用: 45.80.108.144:80 (成功率: 100.00%)
2025-08-14 17:54:59 - FundAnalysis - DEBUG - logger.py:87 - 代理可用: 188.114.97.153:80 (成功率: 100.00%)
2025-08-14 17:54:59 - FundAnalysis - INFO - logger.py:91 - 已检测 40 个代理，发现 13 个可用
2025-08-14 17:54:59 - FundAnalysis - DEBUG - logger.py:87 - 代理检测失败 102.0.0.118:80: HTTPConnectionPool(host='102.0.0.118', port=80): Max retries exceeded with url: http://ident.me/ (Caused by ProxyError('Unable to connect to proxy', ConnectTimeoutError(<urllib3.connection.HTTPConnection object at 0x7f7d3c850950>, 'Connection to 102.0.0.118 timed out. (connect timeout=10)')))
2025-08-14 17:54:59 - FundAnalysis - DEBUG - logger.py:87 - 代理检测失败 125.25.40.41:32650: HTTPConnectionPool(host='125.25.40.41', port=32650): Max retries exceeded with url: http://ident.me/ (Caused by ProxyError('Unable to connect to proxy', ConnectTimeoutError(<urllib3.connection.HTTPConnection object at 0x7f7d3c6ded50>, 'Connection to 125.25.40.41 timed out. (connect timeout=10)')))
2025-08-14 17:54:59 - FundAnalysis - DEBUG - logger.py:87 - 代理可用: 185.176.24.91:80 (成功率: 100.00%)
2025-08-14 17:55:00 - FundAnalysis - DEBUG - logger.py:87 - 代理可用: 45.159.219.50:80 (成功率: 100.00%)
2025-08-14 17:55:00 - FundAnalysis - DEBUG - logger.py:87 - 代理检测失败 103.197.49.12:8080: HTTPConnectionPool(host='103.197.49.12', port=8080): Max retries exceeded with url: http://httpbin.org/ip (Caused by ProxyError('Unable to connect to proxy', ConnectTimeoutError(<urllib3.connection.HTTPConnection object at 0x7f7d3c8647d0>, 'Connection to 103.197.49.12 timed out. (connect timeout=10)')))
2025-08-14 17:55:00 - FundAnalysis - DEBUG - logger.py:87 - 代理检测失败 190.211.250.139:999: HTTPConnectionPool(host='190.211.250.139', port=999): Max retries exceeded with url: http://ident.me/ (Caused by ProxyError('Unable to connect to proxy', ConnectTimeoutError(<urllib3.connection.HTTPConnection object at 0x7f7d3c835090>, 'Connection to 190.211.250.139 timed out. (connect timeout=10)')))
2025-08-14 17:55:00 - FundAnalysis - DEBUG - logger.py:87 - 代理可用: 115.72.14.21:10001 (成功率: 100.00%)
2025-08-14 17:55:02 - FundAnalysis - DEBUG - logger.py:87 - 代理可用: 47.109.83.196:3128 (成功率: 100.00%)
2025-08-14 17:55:02 - FundAnalysis - DEBUG - logger.py:87 - 代理可用: 141.193.213.246:80 (成功率: 100.00%)
2025-08-14 17:55:02 - FundAnalysis - DEBUG - logger.py:87 - 代理可用: 120.26.52.35:3333 (成功率: 100.00%)
2025-08-14 17:55:04 - FundAnalysis - DEBUG - logger.py:87 - 代理检测失败 45.178.174.132:3128: HTTPConnectionPool(host='45.178.174.132', port=3128): Max retries exceeded with url: http://ident.me/ (Caused by ProxyError('Unable to connect to proxy', ConnectTimeoutError(<urllib3.connection.HTTPConnection object at 0x7f7d3c847c50>, 'Connection to 45.178.174.132 timed out. (connect timeout=10)')))
2025-08-14 17:55:06 - FundAnalysis - DEBUG - logger.py:87 - 代理检测失败 119.18.149.9:5020: HTTPConnectionPool(host='119.18.149.9', port=5020): Max retries exceeded with url: http://icanhazip.com/ (Caused by ProxyError('Unable to connect to proxy', ConnectTimeoutError(<urllib3.connection.HTTPConnection object at 0x7f7d3c85e6d0>, 'Connection to 119.18.149.9 timed out. (connect timeout=10)')))
2025-08-14 17:55:09 - FundAnalysis - DEBUG - logger.py:87 - 代理检测失败 159.8.114.37:80: HTTPConnectionPool(host='159.8.114.37', port=80): Max retries exceeded with url: http://ident.me/ (Caused by ProxyError('Unable to connect to proxy', ConnectTimeoutError(<urllib3.connection.HTTPConnection object at 0x7f7d3c6e2a50>, 'Connection to 159.8.114.37 timed out. (connect timeout=10)')))
2025-08-14 17:55:09 - FundAnalysis - DEBUG - logger.py:87 - 代理检测失败 102.216.69.176:8080: HTTPConnectionPool(host='102.216.69.176', port=8080): Max retries exceeded with url: http://httpbin.org/ip (Caused by ProxyError('Unable to connect to proxy', ConnectTimeoutError(<urllib3.connection.HTTPConnection object at 0x7f7d3c827790>, 'Connection to 102.216.69.176 timed out. (connect timeout=10)')))
2025-08-14 17:55:09 - FundAnalysis - DEBUG - logger.py:87 - 代理检测失败 180.183.97.16:8080: HTTPConnectionPool(host='180.183.97.16', port=8080): Max retries exceeded with url: http://ident.me/ (Caused by ProxyError('Unable to connect to proxy', ConnectTimeoutError(<urllib3.connection.HTTPConnection object at 0x7f7d425a2410>, 'Connection to 180.183.97.16 timed out. (connect timeout=10)')))
2025-08-14 17:55:09 - FundAnalysis - DEBUG - logger.py:87 - 代理检测失败 207.248.3.81:999: HTTPConnectionPool(host='207.248.3.81', port=999): Max retries exceeded with url: http://httpbin.org/ip (Caused by ProxyError('Unable to connect to proxy', ConnectTimeoutError(<urllib3.connection.HTTPConnection object at 0x7f7d3c6e2e10>, 'Connection to 207.248.3.81 timed out. (connect timeout=10)')))
2025-08-14 17:55:09 - FundAnalysis - DEBUG - logger.py:87 - 代理检测失败 188.34.164.99:8080: HTTPConnectionPool(host='188.34.164.99', port=8080): Max retries exceeded with url: http://icanhazip.com/ (Caused by ProxyError('Unable to connect to proxy', ConnectTimeoutError(<urllib3.connection.HTTPConnection object at 0x7f7d3c874210>, 'Connection to 188.34.164.99 timed out. (connect timeout=10)')))
2025-08-14 17:55:09 - FundAnalysis - DEBUG - logger.py:87 - 代理检测失败 103.137.91.250:8080: HTTPConnectionPool(host='103.137.91.250', port=8080): Max retries exceeded with url: http://ipinfo.io/ip (Caused by ProxyError('Unable to connect to proxy', ConnectTimeoutError(<urllib3.connection.HTTPConnection object at 0x7f7d3c6f5090>, 'Connection to 103.137.91.250 timed out. (connect timeout=10)')))
2025-08-14 17:55:09 - FundAnalysis - DEBUG - logger.py:87 - 代理检测失败 176.113.73.104:3128: HTTPConnectionPool(host='176.113.73.104', port=3128): Max retries exceeded with url: http://icanhazip.com/ (Caused by ProxyError('Unable to connect to proxy', ConnectTimeoutError(<urllib3.connection.HTTPConnection object at 0x7f7d3c836d50>, 'Connection to 176.113.73.104 timed out. (connect timeout=10)')))
2025-08-14 17:55:09 - FundAnalysis - INFO - logger.py:91 - 已检测 60 个代理，发现 19 个可用
2025-08-14 17:55:09 - FundAnalysis - DEBUG - logger.py:87 - 代理检测失败 115.221.242.131:9999: HTTPConnectionPool(host='115.221.242.131', port=9999): Max retries exceeded with url: http://ipinfo.io/ip (Caused by ProxyError('Unable to connect to proxy', ConnectTimeoutError(<urllib3.connection.HTTPConnection object at 0x7f7d3c840bd0>, 'Connection to 115.221.242.131 timed out. (connect timeout=10)')))
2025-08-14 17:55:09 - FundAnalysis - DEBUG - logger.py:87 - 代理检测失败 190.116.2.52:80: HTTPConnectionPool(host='190.116.2.52', port=80): Max retries exceeded with url: http://ident.me/ (Caused by ProxyError('Unable to connect to proxy', ConnectTimeoutError(<urllib3.connection.HTTPConnection object at 0x7f7d3c850190>, 'Connection to 190.116.2.52 timed out. (connect timeout=10)')))
2025-08-14 17:55:09 - FundAnalysis - DEBUG - logger.py:87 - 代理可用: 45.80.111.212:80 (成功率: 100.00%)
2025-08-14 17:55:09 - FundAnalysis - DEBUG - logger.py:87 - 代理检测失败 187.49.176.141:8080: HTTPConnectionPool(host='187.49.176.141', port=8080): Max retries exceeded with url: http://icanhazip.com/ (Caused by ProxyError('Unable to connect to proxy', ConnectTimeoutError(<urllib3.connection.HTTPConnection object at 0x7f7d425af310>, 'Connection to 187.49.176.141 timed out. (connect timeout=10)')))
2025-08-14 17:55:09 - FundAnalysis - DEBUG - logger.py:87 - 代理检测失败 139.180.140.254:1080: HTTPConnectionPool(host='139.180.140.254', port=1080): Max retries exceeded with url: http://icanhazip.com/ (Caused by ProxyError('Unable to connect to proxy', ConnectTimeoutError(<urllib3.connection.HTTPConnection object at 0x7f7d3c8284d0>, 'Connection to 139.180.140.254 timed out. (connect timeout=10)')))
2025-08-14 17:55:09 - FundAnalysis - DEBUG - logger.py:87 - 代理检测失败 187.141.184.235:8080: HTTPConnectionPool(host='187.141.184.235', port=8080): Max retries exceeded with url: http://icanhazip.com/ (Caused by ProxyError('Unable to connect to proxy', ConnectTimeoutError(<urllib3.connection.HTTPConnection object at 0x7f7d3c81bc50>, 'Connection to 187.141.184.235 timed out. (connect timeout=10)')))
2025-08-14 17:55:09 - FundAnalysis - DEBUG - logger.py:87 - 代理检测失败 52.41.249.10:80: HTTPConnectionPool(host='52.41.249.10', port=80): Max retries exceeded with url: http://ident.me/ (Caused by ProxyError('Unable to connect to proxy', ConnectTimeoutError(<urllib3.connection.HTTPConnection object at 0x7f7d3c693850>, 'Connection to 52.41.249.10 timed out. (connect timeout=10)')))
2025-08-14 17:55:09 - FundAnalysis - DEBUG - logger.py:87 - 代理检测失败 103.231.239.166:58080: HTTPConnectionPool(host='103.231.239.166', port=58080): Max retries exceeded with url: http://ipinfo.io/ip (Caused by ProxyError('Unable to connect to proxy', RemoteDisconnected('Remote end closed connection without response')))
2025-08-14 17:55:09 - FundAnalysis - DEBUG - logger.py:87 - 代理可用: 104.25.113.132:80 (成功率: 100.00%)
2025-08-14 17:55:10 - FundAnalysis - DEBUG - logger.py:87 - 代理检测失败 201.229.250.21:8080: HTTPConnectionPool(host='201.229.250.21', port=8080): Max retries exceeded with url: http://ipinfo.io/ip (Caused by ProxyError('Unable to connect to proxy', ConnectTimeoutError(<urllib3.connection.HTTPConnection object at 0x7f7d3c6f7590>, 'Connection to 201.229.250.21 timed out. (connect timeout=10)')))
2025-08-14 17:55:10 - FundAnalysis - DEBUG - logger.py:87 - 代理检测失败 103.81.175.218:28022: HTTPConnectionPool(host='103.81.175.218', port=28022): Max retries exceeded with url: http://ipinfo.io/ip (Caused by ProxyError('Unable to connect to proxy', ConnectTimeoutError(<urllib3.connection.HTTPConnection object at 0x7f7d3c82ad90>, 'Connection to 103.81.175.218 timed out. (connect timeout=10)')))
2025-08-14 17:55:12 - FundAnalysis - DEBUG - logger.py:87 - 代理可用: 177.73.136.29:8080 (成功率: 100.00%)
2025-08-14 17:55:12 - FundAnalysis - DEBUG - logger.py:87 - 代理检测失败 103.254.106.58:8080: HTTPConnectionPool(host='103.254.106.58', port=8080): Max retries exceeded with url: http://httpbin.org/ip (Caused by ProxyError('Unable to connect to proxy', ConnectTimeoutError(<urllib3.connection.HTTPConnection object at 0x7f7d3c829910>, 'Connection to 103.254.106.58 timed out. (connect timeout=10)')))
2025-08-14 17:55:12 - FundAnalysis - DEBUG - logger.py:87 - 代理检测失败 191.97.16.160:999: HTTPConnectionPool(host='191.97.16.160', port=999): Max retries exceeded with url: http://icanhazip.com/ (Caused by ProxyError('Unable to connect to proxy', ConnectTimeoutError(<urllib3.connection.HTTPConnection object at 0x7f7d3c703910>, 'Connection to 191.97.16.160 timed out. (connect timeout=10)')))
2025-08-14 17:55:12 - FundAnalysis - DEBUG - logger.py:87 - 代理检测失败 190.69.157.213:999: HTTPConnectionPool(host='190.69.157.213', port=999): Max retries exceeded with url: http://ipinfo.io/ip (Caused by ProxyError('Unable to connect to proxy', NewConnectionError('<urllib3.connection.HTTPConnection object at 0x7f7d3c6d7e90>: Failed to establish a new connection: [Errno 111] Connection refused')))
2025-08-14 17:55:12 - FundAnalysis - INFO - logger.py:91 - 已检测 80 个代理，发现 22 个可用
2025-08-14 17:55:14 - FundAnalysis - DEBUG - logger.py:87 - 代理可用: 39.102.211.64:8081 (成功率: 100.00%)
2025-08-14 17:55:14 - FundAnalysis - DEBUG - logger.py:87 - 代理可用: 154.92.9.29:80 (成功率: 100.00%)
2025-08-14 17:55:14 - FundAnalysis - DEBUG - logger.py:87 - 代理检测失败 91.107.203.75:8080: HTTPConnectionPool(host='91.107.203.75', port=8080): Max retries exceeded with url: http://icanhazip.com/ (Caused by ProxyError('Unable to connect to proxy', ConnectTimeoutError(<urllib3.connection.HTTPConnection object at 0x7f7d3c6e11d0>, 'Connection to 91.107.203.75 timed out. (connect timeout=10)')))
2025-08-14 17:55:16 - FundAnalysis - DEBUG - logger.py:87 - 代理检测失败 45.134.14.181:1080: HTTPConnectionPool(host='45.134.14.181', port=1080): Max retries exceeded with url: http://ipinfo.io/ip (Caused by ProxyError('Unable to connect to proxy', ConnectTimeoutError(<urllib3.connection.HTTPConnection object at 0x7f7d3c865b50>, 'Connection to 45.134.14.181 timed out. (connect timeout=10)')))
2025-08-14 17:55:16 - FundAnalysis - DEBUG - logger.py:87 - 代理可用: 38.147.98.190:8080 (成功率: 100.00%)
2025-08-14 17:55:17 - FundAnalysis - DEBUG - logger.py:87 - 代理检测失败 41.204.63.118:80: HTTPSConnectionPool(host='repository.ensign.edu.ghip', port=443): Max retries exceeded with url: / (Caused by ProxyError('Unable to connect to proxy', OSError('Tunnel connection failed: 302 Found')))
2025-08-14 17:55:18 - FundAnalysis - DEBUG - logger.py:87 - 代理可用: 23.171.9.140:8888 (成功率: 100.00%)
2025-08-14 17:55:18 - FundAnalysis - DEBUG - logger.py:87 - 代理可用: 18.135.100.214:3128 (成功率: 100.00%)
2025-08-14 17:55:19 - FundAnalysis - DEBUG - logger.py:87 - 代理检测失败 200.54.22.74:8080: HTTPConnectionPool(host='200.54.22.74', port=8080): Max retries exceeded with url: http://icanhazip.com/ (Caused by ProxyError('Unable to connect to proxy', ConnectTimeoutError(<urllib3.connection.HTTPConnection object at 0x7f7d3c85c350>, 'Connection to 200.54.22.74 timed out. (connect timeout=10)')))
2025-08-14 17:55:19 - FundAnalysis - DEBUG - logger.py:87 - 代理检测失败 43.246.201.53:23654: HTTPConnectionPool(host='43.246.201.53', port=23654): Max retries exceeded with url: http://ipinfo.io/ip (Caused by ProxyError('Unable to connect to proxy', ConnectTimeoutError(<urllib3.connection.HTTPConnection object at 0x7f7d425a2710>, 'Connection to 43.246.201.53 timed out. (connect timeout=10)')))
2025-08-14 17:55:19 - FundAnalysis - DEBUG - logger.py:87 - 代理检测失败 187.21.165.127:8080: HTTPConnectionPool(host='187.21.165.127', port=8080): Max retries exceeded with url: http://httpbin.org/ip (Caused by ProxyError('Unable to connect to proxy', ConnectTimeoutError(<urllib3.connection.HTTPConnection object at 0x7f7d3c81bc10>, 'Connection to 187.21.165.127 timed out. (connect timeout=10)')))
2025-08-14 17:55:19 - FundAnalysis - DEBUG - logger.py:87 - 代理可用: 141.193.213.94:80 (成功率: 100.00%)
2025-08-14 17:55:19 - FundAnalysis - DEBUG - logger.py:87 - 代理检测失败 182.160.124.214:6969: HTTPConnectionPool(host='182.160.124.214', port=6969): Max retries exceeded with url: http://icanhazip.com/ (Caused by ProxyError('Unable to connect to proxy', ConnectTimeoutError(<urllib3.connection.HTTPConnection object at 0x7f7d3c6f4d50>, 'Connection to 182.160.124.214 timed out. (connect timeout=10)')))
2025-08-14 17:55:19 - FundAnalysis - DEBUG - logger.py:87 - 代理检测失败 50.122.86.118:80: HTTPConnectionPool(host='50.122.86.118', port=80): Max retries exceeded with url: http://icanhazip.com/ (Caused by ProxyError('Unable to connect to proxy', ConnectTimeoutError(<urllib3.connection.HTTPConnection object at 0x7f7d3c851290>, 'Connection to 50.122.86.118 timed out. (connect timeout=10)')))
2025-08-14 17:55:19 - FundAnalysis - DEBUG - logger.py:87 - 代理检测失败 43.255.113.232:84: HTTPConnectionPool(host='43.255.113.232', port=84): Max retries exceeded with url: http://ident.me/ (Caused by ProxyError('Unable to connect to proxy', ConnectTimeoutError(<urllib3.connection.HTTPConnection object at 0x7f7d3c81a110>, 'Connection to 43.255.113.232 timed out. (connect timeout=10)')))
2025-08-14 17:55:19 - FundAnalysis - DEBUG - logger.py:87 - 代理检测失败 167.249.29.218:999: HTTPConnectionPool(host='167.249.29.218', port=999): Max retries exceeded with url: http://icanhazip.com/ (Caused by ProxyError('Unable to connect to proxy', ConnectTimeoutError(<urllib3.connection.HTTPConnection object at 0x7f7d3c6d7c50>, 'Connection to 167.249.29.218 timed out. (connect timeout=10)')))
2025-08-14 17:55:19 - FundAnalysis - DEBUG - logger.py:87 - 代理检测失败 103.28.121.58:80: HTTPConnectionPool(host='103.28.121.58', port=80): Max retries exceeded with url: http://ipinfo.io/ip (Caused by ProxyError('Unable to connect to proxy', ConnectTimeoutError(<urllib3.connection.HTTPConnection object at 0x7f7d3c874d50>, 'Connection to 103.28.121.58 timed out. (connect timeout=10)')))
2025-08-14 17:55:19 - FundAnalysis - INFO - logger.py:91 - 已检测 100 个代理，发现 28 个可用
2025-08-14 17:55:19 - FundAnalysis - DEBUG - logger.py:87 - 代理检测失败 186.103.130.91:8080: HTTPConnectionPool(host='186.103.130.91', port=8080): Max retries exceeded with url: http://httpbin.org/ip (Caused by ProxyError('Unable to connect to proxy', ConnectTimeoutError(<urllib3.connection.HTTPConnection object at 0x7f7d3c8651d0>, 'Connection to 186.103.130.91 timed out. (connect timeout=10)')))
2025-08-14 17:55:19 - FundAnalysis - DEBUG - logger.py:87 - 代理可用: 104.16.5.9:80 (成功率: 100.00%)
2025-08-14 17:55:19 - FundAnalysis - DEBUG - logger.py:87 - 代理检测失败 190.238.231.65:1994: HTTPConnectionPool(host='190.238.231.65', port=1994): Max retries exceeded with url: http://ipinfo.io/ip (Caused by ProxyError('Unable to connect to proxy', ConnectTimeoutError(<urllib3.connection.HTTPConnection object at 0x7f7d3c6dda90>, 'Connection to 190.238.231.65 timed out. (connect timeout=10)')))
2025-08-14 17:55:20 - FundAnalysis - DEBUG - logger.py:87 - 代理检测失败 112.198.18.206:8080: HTTPConnectionPool(host='112.198.18.206', port=8080): Max retries exceeded with url: http://ident.me/ (Caused by ProxyError('Unable to connect to proxy', ConnectTimeoutError(<urllib3.connection.HTTPConnection object at 0x7f7d3c828450>, 'Connection to 112.198.18.206 timed out. (connect timeout=10)')))
2025-08-14 17:55:20 - FundAnalysis - DEBUG - logger.py:87 - 代理检测失败 37.120.162.180:42824: HTTPConnectionPool(host='37.120.162.180', port=42824): Max retries exceeded with url: http://httpbin.org/ip (Caused by ProxyError('Unable to connect to proxy', NewConnectionError('<urllib3.connection.HTTPConnection object at 0x7f7d3c6a8650>: Failed to establish a new connection: [Errno 111] Connection refused')))
2025-08-14 17:55:20 - FundAnalysis - DEBUG - logger.py:87 - 代理检测失败 45.125.222.81:8080: HTTPConnectionPool(host='45.125.222.81', port=8080): Max retries exceeded with url: http://ipinfo.io/ip (Caused by ProxyError('Unable to connect to proxy', ConnectTimeoutError(<urllib3.connection.HTTPConnection object at 0x7f7d3c840610>, 'Connection to 45.125.222.81 timed out. (connect timeout=10)')))
2025-08-14 17:55:20 - FundAnalysis - DEBUG - logger.py:87 - 代理可用: 45.146.163.31:80 (成功率: 100.00%)
2025-08-14 17:55:20 - FundAnalysis - DEBUG - logger.py:87 - 代理可用: 212.183.88.107:80 (成功率: 100.00%)
2025-08-14 17:55:20 - FundAnalysis - DEBUG - logger.py:87 - 代理检测失败 146.59.243.214:80: HTTPConnectionPool(host='146.59.243.214', port=80): Max retries exceeded with url: http://ipinfo.io/ip (Caused by ProxyError('Unable to connect to proxy', ConnectTimeoutError(<urllib3.connection.HTTPConnection object at 0x7f7d3c847590>, 'Connection to 146.59.243.214 timed out. (connect timeout=10)')))
2025-08-14 17:55:21 - FundAnalysis - DEBUG - logger.py:87 - 代理检测失败 27.71.140.43:16000: HTTPConnectionPool(host='27.71.140.43', port=16000): Read timed out. (read timeout=10)
2025-08-14 17:55:21 - FundAnalysis - DEBUG - logger.py:87 - 代理可用: 47.116.210.163:8008 (成功率: 100.00%)
2025-08-14 17:55:21 - FundAnalysis - DEBUG - logger.py:87 - 代理可用: 120.25.189.254:8080 (成功率: 100.00%)
2025-08-14 17:55:22 - FundAnalysis - DEBUG - logger.py:87 - 代理可用: 47.121.129.129:9098 (成功率: 100.00%)
2025-08-14 17:55:22 - FundAnalysis - DEBUG - logger.py:87 - 代理检测失败 34.126.187.77:80: HTTPConnectionPool(host='34.126.187.77', port=80): Max retries exceeded with url: http://httpbin.org/ip (Caused by ProxyError('Unable to connect to proxy', ConnectTimeoutError(<urllib3.connection.HTTPConnection object at 0x7f7d3c690850>, 'Connection to 34.126.187.77 timed out. (connect timeout=10)')))
2025-08-14 17:55:22 - FundAnalysis - DEBUG - logger.py:87 - 代理检测失败 102.38.17.193:8080: HTTPConnectionPool(host='102.38.17.193', port=8080): Max retries exceeded with url: http://ipinfo.io/ip (Caused by ProxyError('Unable to connect to proxy', NewConnectionError('<urllib3.connection.HTTPConnection object at 0x7f7d3c85f150>: Failed to establish a new connection: [Errno 111] Connection refused')))
2025-08-14 17:55:22 - FundAnalysis - DEBUG - logger.py:87 - 代理检测失败 46.160.129.189:3128: HTTPConnectionPool(host='46.160.129.189', port=3128): Max retries exceeded with url: http://icanhazip.com/ (Caused by ProxyError('Unable to connect to proxy', ConnectTimeoutError(<urllib3.connection.HTTPConnection object at 0x7f7d3c82b610>, 'Connection to 46.160.129.189 timed out. (connect timeout=10)')))
2025-08-14 17:55:23 - FundAnalysis - DEBUG - logger.py:87 - 代理可用: 27.79.255.136:16000 (成功率: 100.00%)
2025-08-14 17:55:23 - FundAnalysis - DEBUG - logger.py:87 - 代理可用: 181.57.131.122:8080 (成功率: 100.00%)
2025-08-14 17:55:23 - FundAnalysis - INFO - logger.py:91 - 已检测 120 个代理，发现 36 个可用
2025-08-14 17:55:24 - FundAnalysis - DEBUG - logger.py:87 - 代理可用: 4.195.16.140:80 (成功率: 100.00%)
2025-08-14 17:55:24 - FundAnalysis - DEBUG - logger.py:87 - 代理检测失败 181.212.41.171:999: HTTPConnectionPool(host='181.212.41.171', port=999): Max retries exceeded with url: http://httpbin.org/ip (Caused by ProxyError('Unable to connect to proxy', ConnectTimeoutError(<urllib3.connection.HTTPConnection object at 0x7f7d3c702250>, 'Connection to 181.212.41.171 timed out. (connect timeout=10)')))
2025-08-14 17:55:24 - FundAnalysis - DEBUG - logger.py:87 - 代理检测失败 223.113.89.138:1080: HTTPConnectionPool(host='223.113.89.138', port=1080): Max retries exceeded with url: http://ident.me/ (Caused by ProxyError('Unable to connect to proxy', NewConnectionError('<urllib3.connection.HTTPConnection object at 0x7f7d3c6f6bd0>: Failed to establish a new connection: [Errno 111] Connection refused')))
2025-08-14 17:55:24 - FundAnalysis - DEBUG - logger.py:87 - 代理可用: 5.182.34.177:80 (成功率: 100.00%)
2025-08-14 17:55:25 - FundAnalysis - DEBUG - logger.py:87 - 代理可用: 159.112.235.190:80 (成功率: 100.00%)
2025-08-14 17:55:26 - FundAnalysis - DEBUG - logger.py:87 - 代理检测失败 103.245.109.57:39355: HTTPConnectionPool(host='103.245.109.57', port=39355): Max retries exceeded with url: http://httpbin.org/ip (Caused by ProxyError('Unable to connect to proxy', ConnectTimeoutError(<urllib3.connection.HTTPConnection object at 0x7f7d3c837110>, 'Connection to 103.245.109.57 timed out. (connect timeout=10)')))
2025-08-14 17:55:27 - FundAnalysis - DEBUG - logger.py:87 - 代理检测失败 186.208.81.214:3129: HTTPConnectionPool(host='186.208.81.214', port=3129): Max retries exceeded with url: http://httpbin.org/ip (Caused by ProxyError('Unable to connect to proxy', ConnectTimeoutError(<urllib3.connection.HTTPConnection object at 0x7f7d42a79810>, 'Connection to 186.208.81.214 timed out. (connect timeout=10)')))
2025-08-14 17:55:28 - FundAnalysis - DEBUG - logger.py:87 - 代理可用: 42.118.1.127:16000 (成功率: 100.00%)
2025-08-14 17:55:29 - FundAnalysis - DEBUG - logger.py:87 - 代理检测失败 113.195.224.222:9999: HTTPConnectionPool(host='113.195.224.222', port=9999): Max retries exceeded with url: http://httpbin.org/ip (Caused by ProxyError('Unable to connect to proxy', ConnectTimeoutError(<urllib3.connection.HTTPConnection object at 0x7f7d3c6e1350>, 'Connection to 113.195.224.222 timed out. (connect timeout=10)')))
2025-08-14 17:55:29 - FundAnalysis - DEBUG - logger.py:87 - 代理检测失败 183.88.184.48:8080: HTTPConnectionPool(host='183.88.184.48', port=8080): Max retries exceeded with url: http://ipinfo.io/ip (Caused by ProxyError('Unable to connect to proxy', ConnectTimeoutError(<urllib3.connection.HTTPConnection object at 0x7f7d3c702650>, 'Connection to 183.88.184.48 timed out. (connect timeout=10)')))
2025-08-14 17:55:29 - FundAnalysis - DEBUG - logger.py:87 - 代理检测失败 142.11.222.22:80: HTTPConnectionPool(host='142.11.222.22', port=80): Max retries exceeded with url: http://icanhazip.com/ (Caused by ProxyError('Unable to connect to proxy', ConnectTimeoutError(<urllib3.connection.HTTPConnection object at 0x7f7d3c846fd0>, 'Connection to 142.11.222.22 timed out. (connect timeout=10)')))
2025-08-14 17:55:29 - FundAnalysis - DEBUG - logger.py:87 - 代理可用: 206.238.238.146:80 (成功率: 100.00%)
2025-08-14 17:55:29 - FundAnalysis - DEBUG - logger.py:87 - 代理检测失败 51.158.68.68:8811: HTTPConnectionPool(host='51.158.68.68', port=8811): Max retries exceeded with url: http://ipinfo.io/ip (Caused by ProxyError('Unable to connect to proxy', ConnectTimeoutError(<urllib3.connection.HTTPConnection object at 0x7f7d3c6de410>, 'Connection to 51.158.68.68 timed out. (connect timeout=10)')))
2025-08-14 17:55:29 - FundAnalysis - DEBUG - logger.py:87 - 代理检测失败 204.199.140.9:999: HTTPConnectionPool(host='204.199.140.9', port=999): Max retries exceeded with url: http://ipinfo.io/ip (Caused by ProxyError('Unable to connect to proxy', ConnectTimeoutError(<urllib3.connection.HTTPConnection object at 0x7f7d3c85c310>, 'Connection to 204.199.140.9 timed out. (connect timeout=10)')))
2025-08-14 17:55:29 - FundAnalysis - DEBUG - logger.py:87 - 代理可用: 186.231.33.58:61804 (成功率: 100.00%)
2025-08-14 17:55:29 - FundAnalysis - INFO - logger.py:91 - 已检测 140 个代理，发现 42 个可用
2025-08-14 17:55:29 - FundAnalysis - DEBUG - logger.py:87 - 代理检测失败 152.231.25.114:8080: HTTPConnectionPool(host='152.231.25.114', port=8080): Max retries exceeded with url: http://httpbin.org/ip (Caused by ProxyError('Unable to connect to proxy', NewConnectionError('<urllib3.connection.HTTPConnection object at 0x7f7d3ca0a390>: Failed to establish a new connection: [Errno 111] Connection refused')))
2025-08-14 17:55:29 - FundAnalysis - DEBUG - logger.py:87 - 代理检测失败 103.220.206.138:59417: HTTPConnectionPool(host='103.220.206.138', port=59417): Max retries exceeded with url: http://ident.me/ (Caused by ProxyError('Unable to connect to proxy', ConnectTimeoutError(<urllib3.connection.HTTPConnection object at 0x7f7d41a97a90>, 'Connection to 103.220.206.138 timed out. (connect timeout=10)')))
2025-08-14 17:55:30 - FundAnalysis - DEBUG - logger.py:87 - 代理检测失败 38.3.162.129:999: HTTPConnectionPool(host='38.3.162.129', port=999): Max retries exceeded with url: http://ipinfo.io/ip (Caused by ProxyError('Unable to connect to proxy', ConnectTimeoutError(<urllib3.connection.HTTPConnection object at 0x7f7d3c80c810>, 'Connection to 38.3.162.129 timed out. (connect timeout=10)')))
2025-08-14 17:55:30 - FundAnalysis - DEBUG - logger.py:87 - 代理检测失败 103.112.130.14:8080: HTTPConnectionPool(host='103.112.130.14', port=8080): Max retries exceeded with url: http://ident.me/ (Caused by ProxyError('Unable to connect to proxy', ConnectTimeoutError(<urllib3.connection.HTTPConnection object at 0x7f7d4287f3d0>, 'Connection to 103.112.130.14 timed out. (connect timeout=10)')))
2025-08-14 17:55:31 - FundAnalysis - DEBUG - logger.py:87 - 代理检测失败 45.235.200.32:4000: HTTPConnectionPool(host='45.235.200.32', port=4000): Max retries exceeded with url: http://ipinfo.io/ip (Caused by ProxyError('Unable to connect to proxy', ConnectTimeoutError(<urllib3.connection.HTTPConnection object at 0x7f7d4287d110>, 'Connection to 45.235.200.32 timed out. (connect timeout=10)')))
2025-08-14 17:55:31 - FundAnalysis - DEBUG - logger.py:87 - 代理检测失败 3.24.178.81:80: HTTPConnectionPool(host='3.24.178.81', port=80): Max retries exceeded with url: http://httpbin.org/ip (Caused by ProxyError('Unable to connect to proxy', ConnectTimeoutError(<urllib3.connection.HTTPConnection object at 0x7f7d3ca08c10>, 'Connection to 3.24.178.81 timed out. (connect timeout=10)')))
2025-08-14 17:55:31 - FundAnalysis - DEBUG - logger.py:87 - 代理可用: 104.18.183.112:80 (成功率: 100.00%)
2025-08-14 17:55:31 - FundAnalysis - DEBUG - logger.py:87 - 代理检测失败 190.58.248.86:80: HTTPConnectionPool(host='190.58.248.86', port=80): Max retries exceeded with url: http://icanhazip.com/ (Caused by ProxyError('Unable to connect to proxy', ConnectTimeoutError(<urllib3.connection.HTTPConnection object at 0x7f7d3c843b50>, 'Connection to 190.58.248.86 timed out. (connect timeout=10)')))
2025-08-14 17:55:32 - FundAnalysis - DEBUG - logger.py:87 - 代理检测失败 113.100.209.184:3128: HTTPConnectionPool(host='113.100.209.184', port=3128): Max retries exceeded with url: http://httpbin.org/ip (Caused by ProxyError('Unable to connect to proxy', ConnectTimeoutError(<urllib3.connection.HTTPConnection object at 0x7f7d3c6f74d0>, 'Connection to 113.100.209.184 timed out. (connect timeout=10)')))
2025-08-14 17:55:32 - FundAnalysis - DEBUG - logger.py:87 - 代理检测失败 181.212.45.226:8080: HTTPConnectionPool(host='181.212.45.226', port=8080): Max retries exceeded with url: http://httpbin.org/ip (Caused by ProxyError('Unable to connect to proxy', ConnectTimeoutError(<urllib3.connection.HTTPConnection object at 0x7f7d3c847190>, 'Connection to 181.212.45.226 timed out. (connect timeout=10)')))
2025-08-14 17:55:33 - FundAnalysis - DEBUG - logger.py:87 - 代理检测失败 27.79.191.125:16000: HTTPConnectionPool(host='27.79.191.125', port=16000): Max retries exceeded with url: http://ipinfo.io/ip (Caused by ProxyError('Unable to connect to proxy', ConnectTimeoutError(<urllib3.connection.HTTPConnection object at 0x7f7d3c837d10>, 'Connection to 27.79.191.125 timed out. (connect timeout=10)')))
2025-08-14 17:55:34 - FundAnalysis - DEBUG - logger.py:87 - 代理检测失败 116.242.89.230:3128: HTTPConnectionPool(host='116.242.89.230', port=3128): Max retries exceeded with url: http://icanhazip.com/ (Caused by ProxyError('Unable to connect to proxy', ConnectTimeoutError(<urllib3.connection.HTTPConnection object at 0x7f7d3c6de150>, 'Connection to 116.242.89.230 timed out. (connect timeout=10)')))
2025-08-14 17:55:34 - FundAnalysis - DEBUG - logger.py:87 - 代理可用: 108.141.130.146:80 (成功率: 100.00%)
2025-08-14 17:55:35 - FundAnalysis - DEBUG - logger.py:87 - 代理检测失败 179.48.11.6:8085: HTTPConnectionPool(host='179.48.11.6', port=8085): Max retries exceeded with url: http://httpbin.org/ip (Caused by ProxyError('Unable to connect to proxy', ConnectTimeoutError(<urllib3.connection.HTTPConnection object at 0x7f7d3c6e3f90>, 'Connection to 179.48.11.6 timed out. (connect timeout=10)')))
2025-08-14 17:55:36 - FundAnalysis - DEBUG - logger.py:87 - 代理检测失败 84.17.51.240:3128: HTTPConnectionPool(host='84.17.51.240', port=3128): Max retries exceeded with url: http://httpbin.org/ip (Caused by ProxyError('Unable to connect to proxy', ConnectTimeoutError(<urllib3.connection.HTTPConnection object at 0x7f7d3c690b50>, 'Connection to 84.17.51.240 timed out. (connect timeout=10)')))
2025-08-14 17:55:36 - FundAnalysis - DEBUG - logger.py:87 - 代理可用: 138.255.14.20:8080 (成功率: 100.00%)
2025-08-14 17:55:37 - FundAnalysis - DEBUG - logger.py:87 - 代理检测失败 118.99.108.4:8080: HTTPConnectionPool(host='118.99.108.4', port=8080): Max retries exceeded with url: http://ipinfo.io/ip (Caused by ProxyError('Unable to connect to proxy', ConnectTimeoutError(<urllib3.connection.HTTPConnection object at 0x7f7d3c841390>, 'Connection to 118.99.108.4 timed out. (connect timeout=10)')))
2025-08-14 17:55:37 - FundAnalysis - INFO - logger.py:91 - 已检测 160 个代理，发现 45 个可用
2025-08-14 17:55:38 - FundAnalysis - DEBUG - logger.py:87 - 代理检测失败 158.69.185.37:3129: HTTPConnectionPool(host='158.69.185.37', port=3129): Max retries exceeded with url: http://ipinfo.io/ip (Caused by ProxyError('Unable to connect to proxy', ConnectTimeoutError(<urllib3.connection.HTTPConnection object at 0x7f7d3c82a810>, 'Connection to 158.69.185.37 timed out. (connect timeout=10)')))
2025-08-14 17:55:39 - FundAnalysis - DEBUG - logger.py:87 - 代理检测失败 103.114.96.246:8080: HTTPConnectionPool(host='103.114.96.246', port=8080): Max retries exceeded with url: http://icanhazip.com/ (Caused by ProxyError('Unable to connect to proxy', ConnectTimeoutError(<urllib3.connection.HTTPConnection object at 0x7f7d3c6b2f10>, 'Connection to 103.114.96.246 timed out. (connect timeout=10)')))
2025-08-14 17:55:39 - FundAnalysis - DEBUG - logger.py:87 - 代理检测失败 45.188.166.52:1994: HTTPConnectionPool(host='45.188.166.52', port=1994): Max retries exceeded with url: http://ident.me/ (Caused by ProxyError('Unable to connect to proxy', ConnectTimeoutError(<urllib3.connection.HTTPConnection object at 0x7f7d3c834b10>, 'Connection to 45.188.166.52 timed out. (connect timeout=10)')))
2025-08-14 17:55:39 - FundAnalysis - DEBUG - logger.py:87 - 代理检测失败 107.178.9.186:8080: HTTPConnectionPool(host='107.178.9.186', port=8080): Max retries exceeded with url: http://icanhazip.com/ (Caused by ProxyError('Unable to connect to proxy', ConnectTimeoutError(<urllib3.connection.HTTPConnection object at 0x7f7d3c85f490>, 'Connection to 107.178.9.186 timed out. (connect timeout=10)')))
2025-08-14 17:55:39 - FundAnalysis - DEBUG - logger.py:87 - 代理检测失败 121.206.205.75:4216: HTTPConnectionPool(host='121.206.205.75', port=4216): Max retries exceeded with url: http://httpbin.org/ip (Caused by ProxyError('Unable to connect to proxy', ConnectTimeoutError(<urllib3.connection.HTTPConnection object at 0x7f7d3c828210>, 'Connection to 121.206.205.75 timed out. (connect timeout=10)')))
2025-08-14 17:55:39 - FundAnalysis - DEBUG - logger.py:87 - 代理检测失败 13.229.47.109:80: HTTPConnectionPool(host='13.229.47.109', port=80): Max retries exceeded with url: http://ipinfo.io/ip (Caused by ProxyError('Unable to connect to proxy', ConnectTimeoutError(<urllib3.connection.HTTPConnection object at 0x7f7d3ca09c90>, 'Connection to 13.229.47.109 timed out. (connect timeout=10)')))
2025-08-14 17:55:39 - FundAnalysis - DEBUG - logger.py:87 - 代理可用: 116.203.27.109:80 (成功率: 100.00%)
2025-08-14 17:55:39 - FundAnalysis - DEBUG - logger.py:87 - 代理可用: 63.141.128.181:80 (成功率: 100.00%)
2025-08-14 17:55:39 - FundAnalysis - DEBUG - logger.py:87 - 代理检测失败 104.248.59.38:80: HTTPConnectionPool(host='104.248.59.38', port=80): Max retries exceeded with url: http://ipinfo.io/ip (Caused by ProxyError('Unable to connect to proxy', ConnectTimeoutError(<urllib3.connection.HTTPConnection object at 0x7f7d3c6df710>, 'Connection to 104.248.59.38 timed out. (connect timeout=10)')))
2025-08-14 17:55:39 - FundAnalysis - DEBUG - logger.py:87 - 代理检测失败 34.29.41.58:3128: HTTPConnectionPool(host='34.29.41.58', port=3128): Max retries exceeded with url: http://icanhazip.com/ (Caused by ProxyError('Unable to connect to proxy', ConnectTimeoutError(<urllib3.connection.HTTPConnection object at 0x7f7d3c702b10>, 'Connection to 34.29.41.58 timed out. (connect timeout=10)')))
2025-08-14 17:55:39 - FundAnalysis - DEBUG - logger.py:87 - 代理可用: 4.245.123.244:80 (成功率: 100.00%)
2025-08-14 17:55:40 - FundAnalysis - DEBUG - logger.py:87 - 代理检测失败 51.158.68.133:8811: HTTPConnectionPool(host='51.158.68.133', port=8811): Max retries exceeded with url: http://httpbin.org/ip (Caused by ProxyError('Unable to connect to proxy', ConnectTimeoutError(<urllib3.connection.HTTPConnection object at 0x7f7d3c702ed0>, 'Connection to 51.158.68.133 timed out. (connect timeout=10)')))
2025-08-14 17:55:40 - FundAnalysis - DEBUG - logger.py:87 - 代理可用: 200.174.198.86:8888 (成功率: 100.00%)
2025-08-14 17:55:40 - FundAnalysis - DEBUG - logger.py:87 - 代理检测失败 67.43.228.251:28401: HTTPConnectionPool(host='67.43.228.251', port=28401): Max retries exceeded with url: http://icanhazip.com/ (Caused by ProxyError('Unable to connect to proxy', NewConnectionError('<urllib3.connection.HTTPConnection object at 0x7f7d3c836710>: Failed to establish a new connection: [Errno 111] Connection refused')))
2025-08-14 17:55:40 - FundAnalysis - DEBUG - logger.py:87 - 代理检测失败 191.97.19.66:999: HTTPConnectionPool(host='191.97.19.66', port=999): Max retries exceeded with url: http://httpbin.org/ip (Caused by ProxyError('Unable to connect to proxy', ConnectTimeoutError(<urllib3.connection.HTTPConnection object at 0x7f7d3c6a84d0>, 'Connection to 191.97.19.66 timed out. (connect timeout=10)')))
2025-08-14 17:55:40 - FundAnalysis - DEBUG - logger.py:87 - 代理可用: 139.162.78.109:8080 (成功率: 100.00%)
2025-08-14 17:55:41 - FundAnalysis - DEBUG - logger.py:87 - 代理可用: 185.146.173.12:80 (成功率: 100.00%)
2025-08-14 17:55:41 - FundAnalysis - DEBUG - logger.py:87 - 代理检测失败 190.61.88.147:8080: HTTPConnectionPool(host='190.61.88.147', port=8080): Max retries exceeded with url: http://icanhazip.com/ (Caused by ProxyError('Unable to connect to proxy', ConnectTimeoutError(<urllib3.connection.HTTPConnection object at 0x7f7d4287e610>, 'Connection to 190.61.88.147 timed out. (connect timeout=10)')))
2025-08-14 17:55:41 - FundAnalysis - DEBUG - logger.py:87 - 代理检测失败 179.228.241.22:8080: HTTPConnectionPool(host='179.228.241.22', port=8080): Max retries exceeded with url: http://ipinfo.io/ip (Caused by ProxyError('Unable to connect to proxy', ConnectTimeoutError(<urllib3.connection.HTTPConnection object at 0x7f7d3ca0ad90>, 'Connection to 179.228.241.22 timed out. (connect timeout=10)')))
2025-08-14 17:55:41 - FundAnalysis - DEBUG - logger.py:87 - 代理检测失败 193.176.242.186:80: HTTPConnectionPool(host='193.176.242.186', port=80): Max retries exceeded with url: http://icanhazip.com/ (Caused by ProxyError('Unable to connect to proxy', ConnectTimeoutError(<urllib3.connection.HTTPConnection object at 0x7f7d3c80d110>, 'Connection to 193.176.242.186 timed out. (connect timeout=10)')))
2025-08-14 17:55:42 - FundAnalysis - DEBUG - logger.py:87 - 代理检测失败 103.112.54.21:58080: HTTPConnectionPool(host='103.112.54.21', port=58080): Max retries exceeded with url: http://ident.me/ (Caused by ProxyError('Unable to connect to proxy', ConnectTimeoutError(<urllib3.connection.HTTPConnection object at 0x7f7d3c692110>, 'Connection to 103.112.54.21 timed out. (connect timeout=10)')))
2025-08-14 17:55:43 - FundAnalysis - DEBUG - logger.py:87 - 代理检测失败 131.196.219.128:8080: HTTPConnectionPool(host='131.196.219.128', port=8080): Max retries exceeded with url: http://httpbin.org/ip (Caused by ProxyError('Unable to connect to proxy', ConnectTimeoutError(<urllib3.connection.HTTPConnection object at 0x7f7d3c850790>, 'Connection to 131.196.219.128 timed out. (connect timeout=10)')))
2025-08-14 17:55:44 - FundAnalysis - DEBUG - logger.py:87 - 代理检测失败 45.4.3.89:999: HTTPConnectionPool(host='45.4.3.89', port=999): Max retries exceeded with url: http://httpbin.org/ip (Caused by ProxyError('Unable to connect to proxy', ConnectTimeoutError(<urllib3.connection.HTTPConnection object at 0x7f7d3c85d090>, 'Connection to 45.4.3.89 timed out. (connect timeout=10)')))
2025-08-14 17:55:45 - FundAnalysis - DEBUG - logger.py:87 - 代理检测失败 45.168.49.2:8080: HTTPConnectionPool(host='45.168.49.2', port=8080): Max retries exceeded with url: http://icanhazip.com/ (Caused by ProxyError('Unable to connect to proxy', ConnectTimeoutError(<urllib3.connection.HTTPConnection object at 0x7f7d3c80c450>, 'Connection to 45.168.49.2 timed out. (connect timeout=10)')))
2025-08-14 17:55:46 - FundAnalysis - DEBUG - logger.py:87 - 代理检测失败 190.111.209.207:3128: HTTPConnectionPool(host='190.111.209.207', port=3128): Max retries exceeded with url: http://ipinfo.io/ip (Caused by ProxyError('Unable to connect to proxy', ConnectTimeoutError(<urllib3.connection.HTTPConnection object at 0x7f7d3c6b2290>, 'Connection to 190.111.209.207 timed out. (connect timeout=10)')))
2025-08-14 17:55:46 - FundAnalysis - DEBUG - logger.py:87 - 代理可用: 168.227.40.126:9192 (成功率: 100.00%)
2025-08-14 17:55:46 - FundAnalysis - DEBUG - logger.py:87 - 代理检测失败 193.233.211.25:8085: HTTPConnectionPool(host='193.233.211.25', port=8085): Max retries exceeded with url: http://icanhazip.com/ (Caused by ProxyError('Unable to connect to proxy', ConnectTimeoutError(<urllib3.connection.HTTPConnection object at 0x7f7d3c85d050>, 'Connection to 193.233.211.25 timed out. (connect timeout=10)')))
2025-08-14 17:55:47 - FundAnalysis - DEBUG - logger.py:87 - 代理检测失败 103.124.251.12:8081: HTTPConnectionPool(host='103.124.251.12', port=8081): Max retries exceeded with url: http://httpbin.org/ip (Caused by ProxyError('Unable to connect to proxy', ConnectTimeoutError(<urllib3.connection.HTTPConnection object at 0x7f7d4287c6d0>, 'Connection to 103.124.251.12 timed out. (connect timeout=10)')))
2025-08-14 17:55:49 - FundAnalysis - DEBUG - logger.py:87 - 代理检测失败 177.184.195.168:8080: HTTPConnectionPool(host='177.184.195.168', port=8080): Max retries exceeded with url: http://httpbin.org/ip (Caused by ProxyError('Unable to connect to proxy', ConnectTimeoutError(<urllib3.connection.HTTPConnection object at 0x7f7d3c690790>, 'Connection to 177.184.195.168 timed out. (connect timeout=10)')))
2025-08-14 17:55:49 - FundAnalysis - DEBUG - logger.py:87 - 代理检测失败 144.91.106.93:3128: HTTPConnectionPool(host='144.91.106.93', port=3128): Max retries exceeded with url: http://ident.me/ (Caused by ProxyError('Unable to connect to proxy', ConnectTimeoutError(<urllib3.connection.HTTPConnection object at 0x7f7d3c6aa750>, 'Connection to 144.91.106.93 timed out. (connect timeout=10)')))
2025-08-14 17:55:49 - FundAnalysis - DEBUG - logger.py:87 - 代理检测失败 161.202.226.194:8123: HTTPConnectionPool(host='161.202.226.194', port=8123): Max retries exceeded with url: http://icanhazip.com/ (Caused by ProxyError('Unable to connect to proxy', ConnectTimeoutError(<urllib3.connection.HTTPConnection object at 0x7f7d3c6f4610>, 'Connection to 161.202.226.194 timed out. (connect timeout=10)')))
2025-08-14 17:55:49 - FundAnalysis - DEBUG - logger.py:87 - 代理检测失败 176.113.73.99:3128: HTTPConnectionPool(host='176.113.73.99', port=3128): Max retries exceeded with url: http://httpbin.org/ip (Caused by ProxyError('Unable to connect to proxy', ConnectTimeoutError(<urllib3.connection.HTTPConnection object at 0x7f7d3c6e1490>, 'Connection to 176.113.73.99 timed out. (connect timeout=10)')))
2025-08-14 17:55:49 - FundAnalysis - DEBUG - logger.py:87 - 代理检测失败 103.106.34.49:4995: HTTPConnectionPool(host='103.106.34.49', port=4995): Max retries exceeded with url: http://httpbin.org/ip (Caused by ProxyError('Unable to connect to proxy', ConnectTimeoutError(<urllib3.connection.HTTPConnection object at 0x7f7d3c85e810>, 'Connection to 103.106.34.49 timed out. (connect timeout=10)')))
2025-08-14 17:55:50 - FundAnalysis - DEBUG - logger.py:87 - 代理检测失败 103.114.53.2:8080: HTTPConnectionPool(host='103.114.53.2', port=8080): Max retries exceeded with url: http://ipinfo.io/ip (Caused by ProxyError('Unable to connect to proxy', ConnectTimeoutError(<urllib3.connection.HTTPConnection object at 0x7f7d3c702490>, 'Connection to 103.114.53.2 timed out. (connect timeout=10)')))
2025-08-14 17:55:50 - FundAnalysis - DEBUG - logger.py:87 - 代理检测失败 200.95.184.62:999: HTTPConnectionPool(host='200.95.184.62', port=999): Max retries exceeded with url: http://httpbin.org/ip (Caused by ProxyError('Unable to connect to proxy', ConnectTimeoutError(<urllib3.connection.HTTPConnection object at 0x7f7d3c845010>, 'Connection to 200.95.184.62 timed out. (connect timeout=10)')))
2025-08-14 17:55:50 - FundAnalysis - DEBUG - logger.py:87 - 代理检测失败 176.113.73.102:3128: HTTPConnectionPool(host='176.113.73.102', port=3128): Max retries exceeded with url: http://icanhazip.com/ (Caused by ProxyError('Unable to connect to proxy', ConnectTimeoutError(<urllib3.connection.HTTPConnection object at 0x7f7d3ca09890>, 'Connection to 176.113.73.102 timed out. (connect timeout=10)')))
2025-08-14 17:55:51 - FundAnalysis - DEBUG - logger.py:87 - 代理检测失败 14.241.80.37:8080: HTTPConnectionPool(host='14.241.80.37', port=8080): Max retries exceeded with url: http://ipinfo.io/ip (Caused by ProxyError('Unable to connect to proxy', ConnectTimeoutError(<urllib3.connection.HTTPConnection object at 0x7f7d3ca09650>, 'Connection to 14.241.80.37 timed out. (connect timeout=10)')))
2025-08-14 17:55:51 - FundAnalysis - DEBUG - logger.py:87 - 代理检测失败 119.81.189.194:80: HTTPConnectionPool(host='119.81.189.194', port=80): Max retries exceeded with url: http://ident.me/ (Caused by ProxyError('Unable to connect to proxy', ConnectTimeoutError(<urllib3.connection.HTTPConnection object at 0x7f7d3c8516d0>, 'Connection to 119.81.189.194 timed out. (connect timeout=10)')))
2025-08-14 17:55:51 - FundAnalysis - DEBUG - logger.py:87 - 代理检测失败 43.231.78.203:8080: HTTPConnectionPool(host='43.231.78.203', port=8080): Max retries exceeded with url: http://httpbin.org/ip (Caused by ProxyError('Unable to connect to proxy', ConnectTimeoutError(<urllib3.connection.HTTPConnection object at 0x7f7d3c6aa2d0>, 'Connection to 43.231.78.203 timed out. (connect timeout=10)')))
2025-08-14 17:55:51 - FundAnalysis - INFO - logger.py:91 - 代理列表更新完成，共 50 个可用代理
2025-08-14 17:55:51 - FundAnalysis - INFO - logger.py:91 - 代理自动更新线程已启动
2025-08-14 17:55:51 - FundAnalysis - INFO - logger.py:91 - [代理管理器初始化] 执行成功 (耗时: 63.22秒) - 代理管理器初始化成功，可用代理: 50 个
2025-08-14 17:55:51 - FundAnalysis - INFO - logger.py:91 - [获取基金列表] 开始执行
2025-08-14 17:55:51 - FundAnalysis - INFO - logger.py:91 - [获取基金列表] 开始执行
2025-08-14 17:55:51 - FundAnalysis - DEBUG - logger.py:87 - 请求开始 [1] GET http://fund.eastmoney.com/js/fundcode_search.js
2025-08-14 17:55:51 - FundAnalysis - ERROR - logger.py:99 - 请求失败 http://fund.eastmoney.com/js/fundcode_search.js - 530 Server Error: <none> for url: http://fund.eastmoney.com/js/fundcode_search.js
2025-08-14 17:55:53 - FundAnalysis - DEBUG - logger.py:87 - 请求开始 [2] GET http://fund.eastmoney.com/js/fundcode_search.js
2025-08-14 17:55:53 - FundAnalysis - ERROR - logger.py:99 - 请求失败 http://fund.eastmoney.com/js/fundcode_search.js - 530 Server Error: <none> for url: http://fund.eastmoney.com/js/fundcode_search.js
2025-08-14 17:55:57 - FundAnalysis - DEBUG - logger.py:87 - 请求开始 [3] GET http://fund.eastmoney.com/js/fundcode_search.js
2025-08-14 17:55:57 - FundAnalysis - ERROR - logger.py:99 - 请求失败 http://fund.eastmoney.com/js/fundcode_search.js - 530 Server Error: <none> for url: http://fund.eastmoney.com/js/fundcode_search.js
2025-08-14 17:55:57 - FundAnalysis - ERROR - logger.py:99 - 获取东方财富基金列表失败: 530 Server Error: <none> for url: http://fund.eastmoney.com/js/fundcode_search.js
2025-08-14 17:55:57 - FundAnalysis - WARNING - logger.py:95 - akshare获取基金列表失败: module 'akshare' has no attribute 'fund_em_fund_name'
2025-08-14 17:55:57 - FundAnalysis - INFO - logger.py:91 - [获取基金列表] 执行成功 (耗时: 6.09秒) - 获取到 0 只基金
2025-08-14 17:55:57 - FundAnalysis - WARNING - logger.py:95 - 使用默认基金列表
2025-08-14 17:55:57 - FundAnalysis - DEBUG - logger.py:87 - 基金列表已保存: data/fund_list_20250814_175557.json
2025-08-14 17:55:57 - FundAnalysis - INFO - logger.py:91 - [获取基金列表] 执行成功 (耗时: 6.09秒) - 成功获取 10 只基金信息
2025-08-14 17:55:57 - FundAnalysis - INFO - logger.py:91 - 获取到 10 只基金，开始详细分析
2025-08-14 17:55:57 - FundAnalysis - INFO - logger.py:91 - ============================================================
2025-08-14 17:55:57 - FundAnalysis - INFO - logger.py:91 - 第二阶段：多线程基金分析
2025-08-14 17:55:57 - FundAnalysis - INFO - logger.py:91 - ============================================================
2025-08-14 17:55:57 - FundAnalysis - INFO - logger.py:91 - [并行基金分析] 开始执行 - 开始分析 10 只基金
2025-08-14 17:55:57 - FundAnalysis - DEBUG - logger.py:87 - 开始分析基金: 基金110022 (110022)
2025-08-14 17:55:58 - FundAnalysis - DEBUG - logger.py:87 - 请求开始 [4] GET http://fundgz.1234567.com.cn/js/110022.js
2025-08-14 17:56:01 - FundAnalysis - DEBUG - logger.py:87 - 请求成功 200 http://fundgz.1234567.com.cn/js/110022.js (耗时: 3.510s)
2025-08-14 17:56:01 - FundAnalysis - WARNING - logger.py:95 - 解析基金数据JSON失败: 110022
2025-08-14 17:56:01 - FundAnalysis - DEBUG - logger.py:87 - akshare获取基金110022详情失败: module 'akshare' has no attribute 'fund_em_open_fund_info'
2025-08-14 17:56:01 - FundAnalysis - DEBUG - logger.py:87 - 获取基金110022经理信息失败: module 'akshare' has no attribute 'fund_em_open_fund_info'
2025-08-14 17:56:01 - FundAnalysis - DEBUG - logger.py:87 - 获取基金110022持仓信息失败: module 'akshare' has no attribute 'fund_em_open_fund_info'
2025-08-14 17:56:01 - FundAnalysis - WARNING - logger.py:95 - 无法获取基金详情: 110022
2025-08-14 17:56:01 - FundAnalysis - DEBUG - logger.py:87 - 开始分析基金: 基金519674 (519674)
2025-08-14 17:56:01 - FundAnalysis - DEBUG - logger.py:87 - 请求开始 [5] GET http://fundgz.1234567.com.cn/js/519674.js
2025-08-14 17:56:02 - FundAnalysis - DEBUG - logger.py:87 - 请求成功 200 http://fundgz.1234567.com.cn/js/519674.js (耗时: 1.502s)
2025-08-14 17:56:02 - FundAnalysis - DEBUG - logger.py:87 - akshare获取基金519674详情失败: module 'akshare' has no attribute 'fund_em_open_fund_info'
2025-08-14 17:56:02 - FundAnalysis - DEBUG - logger.py:87 - 获取基金519674经理信息失败: module 'akshare' has no attribute 'fund_em_open_fund_info'
2025-08-14 17:56:02 - FundAnalysis - DEBUG - logger.py:87 - 获取基金519674持仓信息失败: module 'akshare' has no attribute 'fund_em_open_fund_info'
2025-08-14 17:56:02 - FundAnalysis - ERROR - logger.py:99 - 获取基金519674历史数据失败: module 'akshare' has no attribute 'fund_em_open_fund_info'
2025-08-14 17:56:02 - FundAnalysis - WARNING - logger.py:95 - 无法获取历史数据: 519674
2025-08-14 17:56:02 - FundAnalysis - DEBUG - logger.py:87 - 开始分析基金: 基金000011 (000011)
2025-08-14 17:56:02 - FundAnalysis - DEBUG - logger.py:87 - 请求开始 [6] GET http://fundgz.1234567.com.cn/js/000011.js
2025-08-14 17:56:02 - FundAnalysis - ERROR - logger.py:99 - 请求失败 http://fundgz.1234567.com.cn/js/000011.js - 403 Client Error: Forbidden for url: http://fundgz.1234567.com.cn/js/000011.js
2025-08-14 17:56:04 - FundAnalysis - DEBUG - logger.py:87 - 请求开始 [7] GET http://fundgz.1234567.com.cn/js/000011.js
2025-08-14 17:56:07 - FundAnalysis - DEBUG - logger.py:87 - 请求成功 200 http://fundgz.1234567.com.cn/js/000011.js (耗时: 2.410s)
2025-08-14 17:56:07 - FundAnalysis - WARNING - logger.py:95 - 解析基金数据JSON失败: 000011
2025-08-14 17:56:07 - FundAnalysis - DEBUG - logger.py:87 - akshare获取基金000011详情失败: module 'akshare' has no attribute 'fund_em_open_fund_info'
2025-08-14 17:56:07 - FundAnalysis - DEBUG - logger.py:87 - 获取基金000011经理信息失败: module 'akshare' has no attribute 'fund_em_open_fund_info'
2025-08-14 17:56:07 - FundAnalysis - DEBUG - logger.py:87 - 获取基金000011持仓信息失败: module 'akshare' has no attribute 'fund_em_open_fund_info'
2025-08-14 17:56:07 - FundAnalysis - WARNING - logger.py:95 - 无法获取基金详情: 000011
2025-08-14 17:56:07 - FundAnalysis - DEBUG - logger.py:87 - 开始分析基金: 基金000001 (000001)
2025-08-14 17:56:07 - FundAnalysis - DEBUG - logger.py:87 - 请求开始 [8] GET http://fundgz.1234567.com.cn/js/000001.js
2025-08-14 17:56:08 - FundAnalysis - DEBUG - logger.py:87 - 请求成功 200 http://fundgz.1234567.com.cn/js/000001.js (耗时: 1.068s)
2025-08-14 17:56:08 - FundAnalysis - DEBUG - logger.py:87 - akshare获取基金000001详情失败: module 'akshare' has no attribute 'fund_em_open_fund_info'
2025-08-14 17:56:08 - FundAnalysis - DEBUG - logger.py:87 - 获取基金000001经理信息失败: module 'akshare' has no attribute 'fund_em_open_fund_info'
2025-08-14 17:56:08 - FundAnalysis - DEBUG - logger.py:87 - 获取基金000001持仓信息失败: module 'akshare' has no attribute 'fund_em_open_fund_info'
2025-08-14 17:56:08 - FundAnalysis - ERROR - logger.py:99 - 获取基金000001历史数据失败: module 'akshare' has no attribute 'fund_em_open_fund_info'
2025-08-14 17:56:08 - FundAnalysis - WARNING - logger.py:95 - 无法获取历史数据: 000001
2025-08-14 17:56:08 - FundAnalysis - DEBUG - logger.py:87 - 开始分析基金: 基金163402 (163402)
2025-08-14 17:56:08 - FundAnalysis - DEBUG - logger.py:87 - 请求开始 [9] GET http://fundgz.1234567.com.cn/js/163402.js
2025-08-14 17:56:10 - FundAnalysis - DEBUG - logger.py:87 - 请求成功 200 http://fundgz.1234567.com.cn/js/163402.js (耗时: 2.415s)
2025-08-14 17:56:10 - FundAnalysis - WARNING - logger.py:95 - 解析基金数据JSON失败: 163402
2025-08-14 17:56:10 - FundAnalysis - DEBUG - logger.py:87 - akshare获取基金163402详情失败: module 'akshare' has no attribute 'fund_em_open_fund_info'
2025-08-14 17:56:10 - FundAnalysis - DEBUG - logger.py:87 - 获取基金163402经理信息失败: module 'akshare' has no attribute 'fund_em_open_fund_info'
2025-08-14 17:56:10 - FundAnalysis - DEBUG - logger.py:87 - 获取基金163402持仓信息失败: module 'akshare' has no attribute 'fund_em_open_fund_info'
2025-08-14 17:56:10 - FundAnalysis - WARNING - logger.py:95 - 无法获取基金详情: 163402
2025-08-14 17:56:10 - FundAnalysis - DEBUG - logger.py:87 - 开始分析基金: 基金000248 (000248)
2025-08-14 17:56:10 - FundAnalysis - DEBUG - logger.py:87 - 请求开始 [10] GET http://fundgz.1234567.com.cn/js/000248.js
2025-08-14 17:56:13 - FundAnalysis - DEBUG - logger.py:87 - 请求成功 200 http://fundgz.1234567.com.cn/js/000248.js (耗时: 2.398s)
2025-08-14 17:56:13 - FundAnalysis - WARNING - logger.py:95 - 解析基金数据JSON失败: 000248
2025-08-14 17:56:13 - FundAnalysis - DEBUG - logger.py:87 - akshare获取基金000248详情失败: module 'akshare' has no attribute 'fund_em_open_fund_info'
2025-08-14 17:56:13 - FundAnalysis - DEBUG - logger.py:87 - 获取基金000248经理信息失败: module 'akshare' has no attribute 'fund_em_open_fund_info'
2025-08-14 17:56:13 - FundAnalysis - DEBUG - logger.py:87 - 获取基金000248持仓信息失败: module 'akshare' has no attribute 'fund_em_open_fund_info'
2025-08-14 17:56:13 - FundAnalysis - WARNING - logger.py:95 - 无法获取基金详情: 000248
2025-08-14 17:56:13 - FundAnalysis - DEBUG - logger.py:87 - 开始分析基金: 基金110003 (110003)
2025-08-14 17:56:13 - FundAnalysis - DEBUG - logger.py:87 - 请求开始 [11] GET http://fundgz.1234567.com.cn/js/110003.js
2025-08-14 17:56:15 - FundAnalysis - DEBUG - logger.py:87 - 请求成功 200 http://fundgz.1234567.com.cn/js/110003.js (耗时: 2.546s)
2025-08-14 17:56:15 - FundAnalysis - WARNING - logger.py:95 - 解析基金数据JSON失败: 110003
2025-08-14 17:56:15 - FundAnalysis - DEBUG - logger.py:87 - akshare获取基金110003详情失败: module 'akshare' has no attribute 'fund_em_open_fund_info'
2025-08-14 17:56:15 - FundAnalysis - DEBUG - logger.py:87 - 获取基金110003经理信息失败: module 'akshare' has no attribute 'fund_em_open_fund_info'
2025-08-14 17:56:15 - FundAnalysis - DEBUG - logger.py:87 - 获取基金110003持仓信息失败: module 'akshare' has no attribute 'fund_em_open_fund_info'
2025-08-14 17:56:15 - FundAnalysis - WARNING - logger.py:95 - 无法获取基金详情: 110003
2025-08-14 17:56:15 - FundAnalysis - DEBUG - logger.py:87 - 开始分析基金: 基金320007 (320007)
2025-08-14 17:56:15 - FundAnalysis - DEBUG - logger.py:87 - 请求开始 [12] GET http://fundgz.1234567.com.cn/js/320007.js
2025-08-14 17:56:20 - FundAnalysis - DEBUG - logger.py:87 - 请求成功 200 http://fundgz.1234567.com.cn/js/320007.js (耗时: 5.310s)
2025-08-14 17:56:20 - FundAnalysis - DEBUG - logger.py:87 - akshare获取基金320007详情失败: module 'akshare' has no attribute 'fund_em_open_fund_info'
2025-08-14 17:56:20 - FundAnalysis - DEBUG - logger.py:87 - 获取基金320007经理信息失败: module 'akshare' has no attribute 'fund_em_open_fund_info'
2025-08-14 17:56:20 - FundAnalysis - DEBUG - logger.py:87 - 获取基金320007持仓信息失败: module 'akshare' has no attribute 'fund_em_open_fund_info'
2025-08-14 17:56:20 - FundAnalysis - ERROR - logger.py:99 - 获取基金320007历史数据失败: module 'akshare' has no attribute 'fund_em_open_fund_info'
2025-08-14 17:56:20 - FundAnalysis - WARNING - logger.py:95 - 无法获取历史数据: 320007
2025-08-14 17:56:20 - FundAnalysis - DEBUG - logger.py:87 - 开始分析基金: 基金100032 (100032)
2025-08-14 17:56:20 - FundAnalysis - DEBUG - logger.py:87 - 请求开始 [13] GET http://fundgz.1234567.com.cn/js/100032.js
2025-08-14 17:56:31 - FundAnalysis - DEBUG - logger.py:87 - 请求成功 200 http://fundgz.1234567.com.cn/js/100032.js (耗时: 10.526s)
2025-08-14 17:56:31 - FundAnalysis - DEBUG - logger.py:87 - akshare获取基金100032详情失败: module 'akshare' has no attribute 'fund_em_open_fund_info'
2025-08-14 17:56:31 - FundAnalysis - DEBUG - logger.py:87 - 获取基金100032经理信息失败: module 'akshare' has no attribute 'fund_em_open_fund_info'
2025-08-14 17:56:31 - FundAnalysis - DEBUG - logger.py:87 - 获取基金100032持仓信息失败: module 'akshare' has no attribute 'fund_em_open_fund_info'
2025-08-14 17:56:31 - FundAnalysis - ERROR - logger.py:99 - 获取基金100032历史数据失败: module 'akshare' has no attribute 'fund_em_open_fund_info'
2025-08-14 17:56:31 - FundAnalysis - WARNING - logger.py:95 - 无法获取历史数据: 100032
2025-08-14 17:56:31 - FundAnalysis - DEBUG - logger.py:87 - 开始分析基金: 基金161725 (161725)
2025-08-14 17:56:31 - FundAnalysis - DEBUG - logger.py:87 - 请求开始 [14] GET http://fundgz.1234567.com.cn/js/161725.js
2025-08-14 18:01:23 - FundAnalysis - DEBUG - logger.py:87 - 请求成功 200 http://fundgz.1234567.com.cn/js/161725.js (耗时: 291.874s)
2025-08-14 18:01:23 - FundAnalysis - DEBUG - logger.py:87 - akshare获取基金161725详情失败: module 'akshare' has no attribute 'fund_em_open_fund_info'
2025-08-14 18:01:23 - FundAnalysis - DEBUG - logger.py:87 - 获取基金161725经理信息失败: module 'akshare' has no attribute 'fund_em_open_fund_info'
2025-08-14 18:01:23 - FundAnalysis - DEBUG - logger.py:87 - 获取基金161725持仓信息失败: module 'akshare' has no attribute 'fund_em_open_fund_info'
2025-08-14 18:01:23 - FundAnalysis - ERROR - logger.py:99 - 获取基金161725历史数据失败: module 'akshare' has no attribute 'fund_em_open_fund_info'
2025-08-14 18:01:23 - FundAnalysis - WARNING - logger.py:95 - 无法获取历史数据: 161725
2025-08-14 18:01:23 - FundAnalysis - INFO - logger.py:91 - [并行基金分析] 进度: 10/10 (100.0%) - 成功: 0, 失败: 10
2025-08-14 18:01:23 - FundAnalysis - INFO - logger.py:91 - [并行基金分析] 执行成功 (耗时: 325.61秒) - 并行分析完成，成功分析 0 只基金
2025-08-14 18:01:23 - FundAnalysis - INFO - logger.py:91 - ============================================================
2025-08-14 18:01:23 - FundAnalysis - INFO - logger.py:91 - 第三阶段：生成综合分析报告
2025-08-14 18:01:23 - FundAnalysis - INFO - logger.py:91 - ============================================================
2025-08-14 18:01:23 - FundAnalysis - INFO - logger.py:91 - [生成综合报告] 开始执行 - 开始生成 0 个基金报告
2025-08-14 18:01:23 - FundAnalysis - INFO - logger.py:91 - [生成综合报告] 执行成功 (耗时: 0.00秒) - 成功生成 0 个基金报告
2025-08-14 18:01:23 - FundAnalysis - INFO - logger.py:91 - ============================================================
2025-08-14 18:01:23 - FundAnalysis - INFO - logger.py:91 - 第四阶段：生成市场总结报告
2025-08-14 18:01:23 - FundAnalysis - INFO - logger.py:91 - ============================================================
2025-08-14 18:01:23 - FundAnalysis - INFO - logger.py:91 - [生成市场总结] 开始执行
2025-08-14 18:01:23 - FundAnalysis - INFO - logger.py:91 - 市场报告已保存: reports/investment_article_20250814_180123.md
2025-08-14 18:01:23 - FundAnalysis - INFO - logger.py:91 - [生成市场总结] 执行成功 (耗时: 0.00秒) - 市场总结报告生成完成
2025-08-14 18:01:23 - FundAnalysis - INFO - logger.py:91 - ============================================================
2025-08-14 18:01:23 - FundAnalysis - INFO - logger.py:91 - 系统运行统计
2025-08-14 18:01:23 - FundAnalysis - INFO - logger.py:91 - ============================================================
2025-08-14 18:01:23 - FundAnalysis - INFO - logger.py:91 - 运行时间: 0:06:34.923410
2025-08-14 18:01:23 - FundAnalysis - INFO - logger.py:91 - 分析基金总数: 0
2025-08-14 18:01:23 - FundAnalysis - INFO - logger.py:91 - 成功分析数量: 0
2025-08-14 18:01:23 - FundAnalysis - INFO - logger.py:91 - 失败分析数量: 10
2025-08-14 18:01:23 - FundAnalysis - INFO - logger.py:91 - 生成报告数量: 0
2025-08-14 18:01:23 - FundAnalysis - INFO - logger.py:91 - ============================================================
2025-08-14 18:01:23 - FundAnalysis - INFO - logger.py:91 - [基金分析系统] 执行成功 (耗时: 394.92秒) - 完整分析流程执行完成，共分析 0 只基金
2025-08-14 18:01:23 - FundAnalysis - INFO - logger.py:91 - 基金数据爬取与分析系统运行完成
2025-08-14 18:01:23 - FundAnalysis - INFO - logger.py:91 - 系统退出
